Workbook

Sheet 機能概要
A2: [BIRD] | C2: 要求仕様書 | N2: 管理番号：DN-030103-019.01 分類 ：要求仕様書 | S2: 更新者：ISID 加藤 更新日：2006/11/28 | W2: 作成者：ISID 加藤 作成日：2006/11/28
A4: 画面名 | D4: 全国大会申込状況確認 | R4: フィーチャ | T4: 申請管理
A6: 機能の目的 | O6: 想定ユーザ
A7: 全国大会への申込状況を確認する。 | O7: 営業推進グループ様
A8: 未登録オーナー様を判別し、登録をうながすことが可能となる。
A10: 機能の概要
A11: 条件画面にて条件と対象を選択し、実行ボタン押下で結果画面を表示する。
A12: 結果画面では、条件画面で選択された条件と対象に合う内容を表示し、表示されている内容をCSVダウンロードする。
A18: 補足説明（用語説明、業務ルールなど）

Sheet 既存画面レイアウト

Sheet 要求仕様
A2: [BIRD] 要求仕様書 | J2: トレーサビリティマトリクス
A4: 画面名 | C4: 全国大会申込状況確認 | H4: フィーチャ | I4: 申請管理 | J4: 条件画面 ビュー | K4: 照会画面 ビュー | L4: 条件 アクション | M4: 照会 アクション | N4: 条件項目情報取得 ロジック | O4: SVコード存在チェック ロジック | P4: 検索対象情報取得 ロジック | Q4: 検索CSV対象出力情報取得 ロジック | R4: 対象エントリー情報 DAO | S4: 支部リスト DAO | T4: SVリスト DAO | U4: 出欠件数情報 DAO | V4: 申込状況一覧 DAO | W4: CSV申込状況一覧 DAO
A5: NO | B5: カテゴリ | C5: 要求番号 | D5: 仕様番号 | E5: 優先 | F5: 分類 | G5: 内容 | H5: 追加変更日 | I5: 備考 | J5: =CONCATENATE(画面構成!G4,"V","01") -> BEN016V01 | K5: =CONCATENATE(画面構成!G4,"V","02") -> BEN016V02 | L5: =CONCATENATE(画面構成!G4,"A","01") -> BEN016A01 | M5: =CONCATENATE(画面構成!G4,"A","02") -> BEN016A02 | N5: =CONCATENATE(画面構成!G4,"L","01") -> BEN016L01 | O5: =CONCATENATE(画面構成!G4,"L","02") -> BEN016L02 | P5: BXX00XL03 | Q5: BXX00XL04 | R5: 対象エントリーデータ | S5: 対象支部データ | T5: 対象SVデータ | U5: ○○データ | V5: 画面用検索結果データ | W5: CSV用検索結果データ
A6: 1 | B6: 条件の設定 | C6: ＦRQ0101 | E6: A | F6: 要求 | G6: 選択された全国大会の申込状況を確認できるようにしてほしい。
C7: ＦRQ0101 | F7: 理由 | G7: 全国大会の参加・不参加のオーナー数、参加人数の把握及び確認を行うため。
C8: ＦRQ0101 | F8: 説明 | G8: 全国大会は２年に１度行われる。
D9: SP010101 | E9: A | F9: 仕様 | G9: この画面は、各種イベント申込状況確認画面より遷移してくる。 | J9: ○
D10: SP010102 | E10: A | F10: 仕様 | G10: 条件部として、①「対象条件」プルダウン、②「表示対象」（デフォルトでは非表示）、③実行ボタンを表示する。 表示項目として、選択された全国大会の「開催日」、「説明会名称」、「本部申込開始」、「本部申込終了」、「オーナー申込開始」、「オーナー申込終了」、「参加」、「不参加」を表示する。 | J10: ○ | L10: ○ | N10: ○
D11: SP010103 | E11: A | F11: 仕様 | G11: ①「対象条件」プルダウンには、「全オーナー」「支部」「SVコード」を一覧し、デフォルトでは「全オーナー」が選択されている状態にする。 | J11: ○
D12: SP010104 | E12: A | F12: 仕様 | G12: 「参加」には全国大会へ参加で申込をしている現在契約中のオーナー数を表示する。 | J12: ○ | L12: ○ | R12: ○
D13: SP010105 | E13: A | F13: 仕様 | G13: 「不参加」には全国大会へ不参加で申込をしている現在契約中のオーナー数を表示する。 | J13: ○ | L13: ○ | R13: ○
D14: SP010106 | E14: A | F14: 仕様 | G14: ③「実行」ボタン押下時、条件にヒットするデータが存在しない場合は、「該当データが存在しません。」のようにメッセージを表示し、現在の画面を再表示する。 | J14: ○ | L14: ○ | U14: ○ | V14: ○
D15: SP010107 | E15: A | F15: 仕様 | G15: ③「実行」ボタン押下時、条件にヒットするデータが存在する場合は、検索結果を表示する。 | J15: ○ | L15: ○ | U15: ○ | V15: ○
C16: ＦRQ0102 | E16: A | F16: 要求 | G16: 表示対象を対象条件に合わせて動的に変えたい。
F17: 理由 | G17: 対象条件によって、入力欄の内容が変わるため。
F18: 説明
C19: ＦRQ0102 | D19: SP010201 | E19: A | F19: 仕様 | G19: 対象条件が「全オーナー」の場合、「表示対象」は表示しない。 ※デフォルトが「全オーナー」のため、デフォルトでは非表示とする。 | J19: ○
C20: ＦRQ0102 | D20: SP010202 | E20: A | F20: 仕様 | G20: 対象条件が全オーナー以外の場合、表示対象を対象条件と実行ボタンの間に表示する。 | J20: ○
C21: ＦRQ0102 | D21: SP010203 | E21: A | F21: 仕様 | G21: 対象条件が「支部」の場合、「表示対象」に支部プルダウンを表示し、デフォルトで一番上の支部を選択しておく。 | J21: ○
C22: ＦRQ0102 | D22: SP010204 | E22: A | F22: 仕様 | G22: 対象条件がSVコードの場合、「表示対象」に入力欄を表示し、最大入力可能文字数は、8文字となるよう制限をかける。また、半角のみ入力可能となるよう制限をかける。 | J22: ○
D23: SP010205 | E23: A | F23: 仕様 | G23: 「対象条件」が「SVコード」の場合、選択ボタン押下で、SV選択画面へ遷移し、SVを選択後、選択されたSVコードをフィールドに反映させる。 | J23: ○ | L23: ○
D24: SP010206 | E24: A | F24: 仕様 | G24: 「対象条件」が「SVコード」で「実行」ボタン押下した場合は、「表示対象」に入力されたSVコードに前0を付加して検索を行う。 | J24: ○ | L24: ○
C25: ＦRQ0103 | E25: A | F25: 要求 | G25: 検索条件のエラーチェックをかけてほしい。
F26: 理由 | G26: 入力ミスによる問題の発生を回避するため。
F27: 説明
D28: SP020302 | E28: A | F28: 仕様 | G28: ③「実行」ボタン押下時、「対象条件」が「SVコード」で、「表示対象」入力欄に半角数値以外の文字が入力されていた場合は、「SVコードは半角数字8桁以内で入力して下さい。」のようにメッセージを表示し、現在の画面を再表示する。 | J28: ○ | L28: ○
D29: SP020303 | E29: A | F29: 仕様 | G29: ③「実行」ボタン押下時、「対象条件」が「SVコード」で、「表示対象」入力欄が空欄の場合は「SVコードを入力してください。」のようにメッセージを表示し、現在の画面を再表示する。 | J29: ○ | L29: ○
D30: SP020303 | E30: A | F30: 仕様 | G30: ③「実行」ボタン押下時、「対象条件」が「SVコード」で、該当SVが存在しない場合は、「該当SVコードが存在しません。」のようにメッセージを表示し、現在の画面を再表示する。 | J30: ○ | L30: ○ | O30: ○ | T30: ○
C31: ＦRQ0205 | E31: A | F31: 要求 | G31: 条件指定については、結果画面上でも再指定ができるようにしたい。
C32: ＦRQ0105 | F32: 理由 | G32: 条件画面と結果画面を行き来するのではなく、結果画面上で連続操作することで作業効率が上がるため。
C33: ＦRQ0105 | F33: 説明 | G33: 一覧検索系画面での標準動作。
C34: ＦRQ0105 | D34: SP020501 | E34: A | F34: 仕様 | G34: 初期表示時のボタン名は「実行」とし、一度正常に結果が表示された後はボタン名は「再検索」とする。 | J34: ○
C35: ＦRQ0105 | D35: SP020502 | E35: A | F35: 仕様 | G35: ③「再検索」押下時、条件にヒットするデータが存在しない場合は、「該当データが存在しません。」というメッセージを表示し、現在の画面を再表示する。 | K35: ○ | M35: ○ | U35: ○ | V35: ○
C36: ＦRQ0105 | D36: SP020503 | E36: A | F36: 仕様 | G36: 条件にヒットするデータが存在する場合は、検索結果を表示する。 | K36: ○ | M36: ○ | P36: ○ | U36: ○ | V36: ○
A37: 2 | B37: 結果の表示 | C37: ＦRQ0301 | E37: A | F37: 要求 | G37: 条件画面で設定された条件での全国大会の申込状況を支部、オーナー単位で表示してほしい。
C38: ＦRQ0201 | F38: 理由 | G38: 未登録オーナーに対して、登録を促すため。
C39: ＦRQ0201 | F39: 説明
C40: ＦRQ0201 | D40: SP030101 | E40: A | F40: 仕様 | G40: 結果画面には条件部として、①「対象条件」プルダウン、②「表示対象」プルダウン、③「実行」ボタンを表示する。 | K40: ○
C41: ＦRQ0201 | D41: SP030102 | E41: A | F41: 仕様 | G41: ヘッダー部として、「開催日」、「説明会名称」、「本部申込開始」、「本部申込終了」、「オーナー申込開始」、「オーナー申込終了」、「参加」、「不参加」、「区分」プルダウン、「ダウンロード」ボタン、「参加オーナー」、「参加人数」、「不参加オーナー」、「未登録オーナー」を表示する。 データ部として、「No.」、「支部」、「オーナー」、「参加」、「参加人数」を表示する。 | K41: ○ | M41: ○ | N41: ○
C42: ＦRQ0201 | D42: SP030103 | E42: A | F42: 仕様 | G42: 「区分」プルダウンには「参加」「不参加」「未登録」を一覧し、デフォルトでは「参加」が選択されている状態にする。 | K42: ○
...

Sheet 画面レイアウト
A2: =画面構成!A2 -> [BIRD] | C2: =画面構成!C2 -> 画面設計書 | N2: 管理番号：DN-030103-019.01 分類 ：要求仕様書 | S2: 更新者：ISID 加藤 更新日：2006/11/28 | W2: 作成者：ISID 加藤 作成日：2006/11/28
A4: 画面レイアウト | E4: 画面ID | G4: =画面構成!G4 -> BEN016 | I4: 画面名 | K4: 各種イベント申込状況確認
A5: ビューID | C5: BEN012V01 | F5: ビュー名 | H5: 各種イベント申込状況確認画面 条件画面 | W5: 備考
A6: JSF名 | C6: businessPlanView | F6: CSS名 | H6: body.css
B8: ■各種イベント申込状況確認
B10: 対象名 | D10: 開催日 | H10: イベント名称 | O10: 申込開始 | R10: 申込終了
B12: 事業方針 | D12: 2006/09/10(日) | H12: 平成１８年度事業方針説明会 | O12: 38950 | R12: 38959
AJ13: 出席
B14: 全国大会 | D14: 2006/11/16(木)～2006/11/17(金) | H14: 平成１８年度開催 全国大会 | O14: 38991 | R14: 39000 | AJ14: 欠席
AJ15: 全て
B16: 店長勉強会 | D16: 2006/12/11(月)～2006/12/12(火) | H16: 平成１８年度開催 全国店長勉強会 | O16: 39022 | R16: 39031 | AJ16: 未登録
A39: ビューID | C39: BEN016V01 | F39: ビュー名 | H39: 全国大会申込状況確認 初期画面 | W39: 備考
A40: JSF名 | C40: NationalView | F40: CSS名 | H40: body.css
B42: ■全国大会申込状況確認
B44: 対象条件 | G44: 表示対象 | N44: 区分 | AD44: 対象条件 | AF44: 支部
W46: ※2006/12/25
B47: 開催日 | F47: イベント名称 | L47: 本部 ：申込開始 | O47: 本部 ：申込終了 | R47: 参加 | T47: 不参加 | W47: レビュー後、文字揃えを | AD47: 全オーナー | AI47: 参加
L48: オーナー：申込開始 | O48: オーナー：申込終了 | W48: BIRD標準にあわせる | AD48: 支部 | AF48: 北海道支部 | AI48: 不参加
B49: 2006/11/16(木)～2006/11/17(金) | F49: 平成１８年度開催 全国大会 | L49: 2006/08/21 | O49: 2006/08/30 | R49: 2 | T49: 1 | AD49: ＳＶコード | AF49: 東北支部 | AI49: 未登録
L50: 2006/08/21 | O50: 2006/08/30 | W50: ※2007/02/02 | AF50: 新潟・群馬・栃木支部
W51: 画面イメージ変更 | AF51: 埼玉支部
W52: 区分を追加 | AF52: 千葉・茨城支部
AF53: 東京支部
AF54: 神奈川支部
AF55: 甲信支部
AF56: 静岡支部
AF57: 中京北陸支部
AF58: 関西支部
AF59: ・・・
A73: ビューID | C73: BEN016V01 | F73: ビュー名 | H73: 全国大会申込状況確認 結果画面 | W73: 備考
A74: JSF名 | C74: NationalView | F74: CSS名 | H74: body.css
B76: ■全国大会申込状況確認
B78: 対象条件 | G78: 表示対象 | O78: 区分
B81: 開催日 | F81: イベント名称 | L81: 本部 ：申込開始 | O81: 本部 ：申込終了 | R81: 参加 | T81: 不参加 | W81: ※2006/12/25
L82: オーナー：申込開始 | O82: オーナー：申込終了 | W82: レビュー後、
B83: 2006/11/16(木)～2006/11/17(金) | F83: 平成１８年度開催 全国大会 | L83: 2006/08/21 | O83: 2006/08/30 | R83: 2 | T83: 1 | W83: 「イベント名称」に変更
L84: 2006/08/21 | O84: 2006/08/30
B86: 参加オーナー | D86: 2 | E86: 参加人数 | G86: 3 | H86: 不参加オーナー | J86: 1 | K86: 未登録オーナー | M86: 500 | W86: ※2006/12/25
W87: レビュー後、文字揃えを
B88: No. | C88: 支部 | G88: オーナー | M88: 参加 | O88: 参加人数 | W88: BIRD標準にあわせる
...

Sheet 画面構成
A2: [BIRD] | C2: 画面設計書 | N2: 管理番号：DN-030103-019.01 分類 ：要求仕様書 | S2: 更新者：ISID 加藤 更新日：2006/11/28 | W2: 作成者：ISID 加藤 作成日：2006/11/28
A4: 画面構成 | E4: 画面ID | G4: BEN016 | I4: 画面名 | K4: 全国大会申込状況確認
A5: 機能概要 | D5: 全国大会の申込状況を確認する。 | S5: 構成概要
A6: パッケージルート | D6: jp.co.isid.mos.bird.entry.nationalviewlist | N6: 画面タイプ | P6: 検索エンジン型 | S6: テーブル | U6: 店統合マスタ（BM01TENM）
S7: テーブル | U7: 汎用店舗グループ（支部）（BM10GSIB）
C8: view | G8: action | L8: logic | P8: dao | S8: テーブル | U8: グループ統合オーナマスタ（BM11ONER）
S9: テーブル | U9: 加盟店スタッフマスタ（BM12STAF）
S10: テーブル | U10: Birdユーザ（BR01USER）
S11: テーブル | U11: エントリーマスタ管理（BR17ENTL）
S12: テーブル | U12: エントリー日付管理（BR18ENTD）
S13: テーブル | U13: エントリーオーナー宛先情報（BT21ENOJ）
S14: テーブル | U14: 全国大会エントリー状況（BT48NATI)
S15: テーブル | U15: エントリーセレクション管理（BR53ENTS)
S16: テーブル | U16: オーナー別エントリー状況(BT20ENON)
S17: テーブル

Sheet コンポーネント一覧
A2: =画面構成!A2 -> [BIRD] | C2: =画面構成!C2 -> 画面設計書 | N2: =画面構成!N2 -> 管理番号：DN-030103-019.01 分類 ：要求仕様書 | S2: =画面構成!S2 -> 更新者：ISID 加藤 更新日：2006/11/28 | W2: =画面構成!W2 -> 作成者：ISID 加藤 作成日：2006/11/28
A4: コンポーネント一覧 | E4: 画面ID | G4: =画面構成!G4 -> BEN016 | I4: 画面名 | K4: =画面構成!K4 -> 全国大会申込状況確認
A5: ビュー名 | C5: 初期画面
A6: 項目名 | D6: 編集 | E6: 表示 | F6: データタイプ | H6: 桁数 | I6: コントロール | K6: 初期値 | N6: 必須 | O6: 対応プロパティ・アクション | T6: 備考
A7: 条件項目エリア
A8: 戻る | D8: × | E8: ○ | F8: - | H8: - | I8: ボタン | K8: - | N8: ○ | O8: 【アクション】全国大会申込状況確認 初期画面.戻る
A9: 対象条件 | D9: ○ | E9: ○ | F9: 全角文字列 | I9: プルダウン | K9: 全オーナー | N9: ○
A10: 支部 | D10: ○ | E10: △ | F10: 全角文字列 | I10: プルダウン | K10: リストの１番目の支部 | N10: ○ | T10: 対象条件が『支部』の場合のみ表示されます。
A11: SVコード | D11: ○ | E11: △ | F11: 半角文字列 | I11: テキスト | K11: - | N11: ○ | T11: 対象条件が『SVコード』の場合のみ表示されます。
A12: SV検索 | D12: × | E12: △ | F12: - | H12: - | I12: ボタン | K12: - | N12: ○ | O12: 【アクション】全国大会申込状況確認 照会画面.SV検索 | T12: 対象条件が『SVコード』の場合のみ表示されます。
A13: 実行 | D13: × | E13: ○ | F13: - | H13: - | I13: ボタン | K13: - | N13: ○ | O13: 【アクション】全国大会申込状況確認 初期画面.実行
A15: 対象エントリー情報エリア
A16: 開催日 | D16: × | E16: ○ | F16: 文字列 | I16: ラベル | K16: - | N16: ○
A17: イベント名称 | D17: × | E17: ○ | F17: 全角文字列 | I17: ラベル | K17: - | N17: ○
A18: 本部：申込開始 | D18: × | E18: ○ | F18: 日付文字列 | I18: ラベル | K18: - | N18: ○
A19: オーナー：申込開始 | D19: × | E19: ○ | F19: 日付文字列 | I19: ラベル | K19: - | N19: ○
A20: 本部：申込終了 | D20: × | E20: ○ | F20: 日付文字列 | I20: ラベル | K20: - | N20: ○
A21: オーナー：申込終了 | D21: × | E21: ○ | F21: 日付文字列 | H21: - | I21: ラベル | K21: - | N21: ○
A22: 参加 | D22: × | E22: ○ | F22: 数値文字列 | I22: ラベル | K22: - | N22: ○
A23: 不参加 | D23: × | E23: ○ | F23: 数値文字列 | I23: ラベル | K23: - | N23: ○
A26: ビュー名 | C26: 照会画面
A27: 項目名 | D27: 編集 | E27: 表示 | F27: データタイプ | H27: 桁数 | I27: コントロール | K27: 初期値 | N27: 必須 | O27: 対応プロパティ・アクション | T27: 備考
A28: 条件項目エリア
A29: 戻る | D29: × | E29: ○ | F29: - | H29: - | I29: ボタン | K29: - | N29: ○ | O29: 【アクション】全国大会申込状況確認 照会画面.戻る
A30: 対象条件 | D30: ○ | E30: ○ | F30: 全角文字列 | I30: プルダウン | K30: 全オーナー | N30: ○
A31: 支部 | D31: ○ | E31: △ | F31: 全角文字列 | I31: プルダウン | K31: リストの１番目の支部 | N31: ○ | T31: 対象条件が『支部』の場合のみ表示されます。
A32: SVコード | D32: ○ | E32: △ | F32: 半角文字列 | I32: テキスト | N32: ○ | T32: 対象条件が『SVコード』の場合のみ表示されます。
A33: SV検索 | D33: × | E33: △ | F33: - | H33: - | I33: ボタン | K33: - | N33: ○ | O33: 【アクション】全国大会申込状況確認 照会画面.SV検索 | T33: 対象条件が『SVコード』の場合のみ表示されます。
A34: 再検索 | D34: × | E34: ○ | F34: - | H34: - | I34: ボタン | K34: - | N34: ○ | O34: 【アクション】全国大会申込状況確認 照会画面.再検索
A36: 対象エントリー情報エリア
A37: 開催日 | D37: × | E37: ○ | F37: 文字列 | I37: ラベル | K37: - | N37: ○
A38: イベント名称 | D38: × | E38: ○ | F38: 全角文字列 | I38: ラベル | K38: - | N38: ○
A39: 本部：申込開始 | D39: × | E39: ○ | F39: 日付文字列 | I39: ラベル | K39: - | N39: ○
A40: オーナー：申込開始 | D40: × | E40: ○ | F40: 日付文字列 | I40: ラベル | K40: - | N40: ○
A41: 本部：申込終了 | D41: × | E41: ○ | F41: 日付文字列 | I41: ラベル | K41: - | N41: ○
A42: オーナー：申込終了 | D42: × | E42: ○ | F42: 日付文字列 | H42: - | I42: ラベル | K42: - | N42: ○
A43: 参加 | D43: × | E43: ○ | F43: 数値文字列 | I43: ラベル | K43: - | N43: ○
A44: 不参加 | D44: × | E44: ○ | F44: 数値文字列 | I44: ラベル | K44: - | N44: ○
A46: 対象エントリー全オーナー参加・不参加件数エリア
A47: 区分 | D47: ○ | E47: △ | F47: 全角文字列 | I47: プルダウン | K47: - | N47: △ | T47: 参加・不参加・未登録
...

Sheet アクション
A2: =画面構成!A2 -> [BIRD] | C2: =画面構成!C2 -> 画面設計書 | N2: =画面構成!N2 -> 管理番号：DN-030103-019.01 分類 ：要求仕様書 | S2: =画面構成!S2 -> 更新者：ISID 加藤 更新日：2006/11/28 | W2: =画面構成!W2 -> 作成者：ISID 加藤 作成日：2006/11/28
A4: アクション | E4: 画面ID | G4: =画面構成!G4 -> BEN016 | I4: 画面名 | K4: =画面構成!K4 -> 全国大会申込状況確認
A5: ビュー名 | C5: 初期画面
A6: アクションID | C6: =CONCATENATE(画面構成!G4, "A", "01") -> BEN016A01 | F6: アクション名 | H6: 初期処理 | R6: 遷移先ビュー | U6: 呼出し元（null）
A7: 事前条件 | J7: 処理概要
J8: １．共通DTO【各種イベント申込状況確認】初期フラグが'1'の場合、下記の処理を行う。
K9: １－１． | L9: 複数WindowID設定
K10: １－２． | L10: DTOの中身を初期化する。
K11: １－３． | L11: 共通画面から値を取得
K12: １－４． | L12: フレームワークより値を取得
K13: １－５． | L13: ロジック【条件項目の取得】を実行する。
K14: パラメーター | M14: BIRDユーザー情報
M15: システム日付
M16: 共通DTO【各種イベント申込状況確認】.エントリーコード
M17: 共通DTO【各種イベント申込状況確認】.エントリー年
M18: 共通DTO【各種イベント申込状況確認】.エントリー回
K19: １－６． | L19: 処理１－５の戻り値から、[[会社リスト]]を取得し、DTO【申込状況確認】.会社リストへ設定する。
K20: １－７． | L20: 処理１－５の戻り値から、[[支部リスト]]を取得し、DTO【申込状況確認】.支部リストへ設定する。
K21: １－８． | L21: 処理１－５の戻り値から、[[対象エントリー情報]]を取得する。
K22: １－９． | L22: 処理１－８の結果の１行目の値のをDTO【申込状況確認】.対象エントリー情報エンティティーへ設定する。
K23: １－１０． | L23: 対象条件プルダウン用リストを生成し、DTO【申込状況確認】.対象条件リストへ設定する。
K24: １－１１． | L24: 区分プルダウン用リストを生成し、DTO【申込状況確認】.区分リストへ設定する。
A25: 事後条件 | K25: １－１２． | L25: 共通DTO【各種イベント申込状況確認】.初期起動フラグを初期値に設定する。
A26: ・｢対象条件｣プルダウンのデフォルトが｢全オーナー｣になっていること | K26: １－１３．DTO【リクエスト用】ウィンドウIDにDTO【SV選択】.ウィンドウIDを設定する。
J28: ２．SV選択画面から遷移してきた場合。
K29: ２－１． | L29: 【DTO】ウィンドウIDにDTO【SV選択】.ウィンドウIDを設定する。
K30: ２－２． | L30: SVを選択後遷移してきた場合、以下の処理を行う。
L31: DTO【申込状況確認】.SVコードへ、DTO【SV選択】.SVコードを設定する。
K32: ２－３． | L32: DTO【SV選択】.遷移区分を初期値に戻す。
K33: ２－４． | L33: DTO【SV選択】.クリア処理を実行する。
K34: ２－５． | L34: DTO【リクエスト用】ウィンドウIDにDTO【SV選択】.ウィンドウIDを設定する。
J36: ３．現ウィンドウIDの保管データから【DTO】検索対象条件項目へ値の設定を行う。
J38: ４．Nullをリターンする。
A39: アクションID | C39: =CONCATENATE(画面構成!G4, "A", "02") -> BEN016A02 | F39: アクション名 | H39: 戻る | R39: 遷移先ビュー | U39: 共通 各種イベント申込確認画面
A40: 事前条件 | J40: 処理概要
J41: １．DTO【申込状況確認】.クリア処理を行う。
J43: ２．共通DTO【各種イベント申込状況確認】.リターンタイプに’戻る’の値を設定する。
A44: 事後条件
A45: ・共通 各種イベント申込確認画面へ遷移すること。 | J45: ３．共通 各種イベント申込確認画面VIEWIDをリターンする。
A49: アクションID | C49: =CONCATENATE(画面構成!G4, "A", "03") -> BEN016A03 | F49: アクション名 | H49: SV検索 | R49: 遷移先ビュー | U49: SV選択画面
...
