Workbook

Sheet 変更履歴
B2: 承認履歴
B4: バージョン | C4: 変更管理NO | D4: 作成 | F4: レビュー | H4: 承認
D5: 担当者 | E5: 日付 | F5: 担当者 | G5: 日付 | H5: 担当者 | I5: 日付
B6: 01 | C6: 201405-001 | D6: 周春建 | E6: 41766 | F6: 王海軍 | G6: 41768
B7: 02 | C7: 201405-001 | D7: 周春建 | E7: 41789 | F7: 王海軍 | G7: 41789
B15: 変更履歴
B17: バージョン | C17: 変更内容
B18: 01 | C18: 【BEN016L03】CSV出力情報取得シート：以下の内容を追加する。 ・オプショナル部の名を取得する ・オプショナルのタイトルを画面の名称も含めて表示する ・生年月日、備考１を追加して、備考を備考２に変換する ・生年月日を「yyyy/mm/nn」フォーマットで表示する ・申込区分の出力内容を名称で表示する
B19: 02 | C19: 【BEN016L03】CSV出力情報取得シートに「年齢再計算する」を追加する。

Sheet 業務ロジック一覧
B1: ロジックNO | C1: 業務ロジック名 | D1: 機能概要 | E1: ルールクラス | F1: ステータス | G1: 更新日 | H1: 担当
B2: BEN016L01 | C2: 条件項目情報の取得 | D2: 登録可能対象事業方針説明会情報を取得します。 | F2: 暫定版
B3: BEN016L02 | C3: 検索対象情報取得 | D3: 登録可能対象事業方針説明会情報を取得します。 | F3: 暫定版
B4: BEN016L03 | C4: CSV出力情報取得 | D4: CSV出力情報を取得します。 | F4: 暫定版
B5: BEN016L04 | C5: SVコード存在チェック | D5: SVコードの存在チェックを行います。 | F5: 暫定版

Sheet 検索
A1: 検索文字列 | C1: ロジックNO | D1: 業務ロジック名 | E1: 機能概要 | F1: ルールクラス | G1: ステータス | H1: 更新日 | I1: 担当
A2: 店コード

Sheet テンプレート
A2: [BIRD]ロジック設計書 | D2: 管理番号：DN-030103-019.01 分類 ：ロジック設計書 | G2: 更新者： 更新日： | I2: 作成者：ISID-IT 衣川 作成日：2006/12/27
A3: （ロジック名）
A4: 機能概要 | B4: 登録可能対象事業方針説明会情報を取得します。 | G4: TX属性 | H4: NotSupported
A5: ロジッククラス | B5: jp.co.isid.mos.bird.entry.nationalviewlist
A6: ロジックNO | B6: BEN016L | C6: ステータス | D6: 暫定版 | J6: ステータスリスト
J7: 暫定版
A8: インタフェース定義 | J8: レビュー待ち
A9: パラメータ | J9: 確定版
A10: 項目名 | B10: データタイプ | C10: 内容 | G10: 必須 | H10: 初期値
A21: リターン
A22: 項目名 | B22: データタイプ | C22: 内容 | G22: 初期値
A29: データI/O定義
A30: 使用Dao名 | C30: Daoクラス名
A40: コントラクト定義
A41: 事前条件 | G41: メッセージID（引数）
A54: 事後条件 | G54: メッセージID（引数）
A66: ロジック定義
A67: 処理内容
A124: ロジック定義
A125: 処理内容

Sheet 【BEN016L01】条件項目情報の取得
A2: [BIRD]ロジック設計書 | D2: =テンプレート!D2 -> 管理番号：DN-030103-019.01 分類 ：ロジック設計書 | G2: =テンプレート!G2 -> 更新者： 更新日： | I2: =テンプレート!I2 -> 作成者：ISID-IT 衣川 作成日：2006/12/27
A3: 条件項目情報の取得
A4: 機能概要 | B4: 登録可能対象事業方針説明会情報を取得します。 | G4: TX属性 | H4: NotSupported
A5: ロジッククラス | B5: =CONCATENATE(テンプレート!B5, ".logic.impl.ConditionLogicImpl") -> jp.co.isid.mos.bird.entry.nationalviewlist.logic.impl.ConditionLogicImpl
A6: ロジックNO | B6: =CONCATENATE(テンプレート!B6,,"01") -> BEN016L01 | C6: ステータス | D6: 暫定版 | J6: ステータスリスト
J7: 暫定版
A8: インタフェース定義 | J8: レビュー待ち
A9: パラメータ | J9: 確定版
A10: 項目名 | B10: データタイプ | C10: 内容 | G10: 必須 | H10: 初期値
A11: BIRDユーザー情報 | B11: BirdUserInfo | G11: ○
A12: システム日付 | B12: 文字列 | G12: ○
A13: 会社コード | B13: 文字列
A14: エントリーコード | B14: 文字列 | G14: ○
A15: エントリー年 | B15: 文字列 | G15: ○
A16: エントリー回 | B16: 文字列 | G16: ○
A20: リターン
A21: 項目名 | B21: データタイプ | C21: 内容 | G21: 初期値
A22: 対象エントリー情報 | B22: List | C22: =CONCATENATE(テンプレート!B5, ".entity.UIEntryStatusInfo") -> jp.co.isid.mos.bird.entry.nationalviewlist.entity.UIEntryStatusInfo
A23: 会社リスト | B23: List | C23: =CONCATENATE(テンプレート!B5, ".entity.CodCompany") -> jp.co.isid.mos.bird.entry.nationalviewlist.entity.CodCompany
A24: 支部リスト | B24: List | C24: =CONCATENATE(テンプレート!B5, ".entity.CodSibu") -> jp.co.isid.mos.bird.entry.nationalviewlist.entity.CodSibu
A27: データI/O定義
A28: 使用Dao名 | C28: Daoクラス名
A29: 対象エントリー情報 | B29: List | C29: =CONCATENATE(テンプレート!B5, ".dao.UIEntryStatusInfoDao") -> jp.co.isid.mos.bird.entry.nationalviewlist.dao.UIEntryStatusInfoDao
A30: 会社リスト | B30: List | C30: =CONCATENATE(テンプレート!B5, ".dao.CodCompanyDao") -> jp.co.isid.mos.bird.entry.nationalviewlist.dao.CodCompanyDao
A31: 支部リスト | B31: List | C31: =CONCATENATE(テンプレート!B5, ".dao.CodSibuDao") -> jp.co.isid.mos.bird.entry.nationalviewlist.dao.CodSibuDao
A34: コントラクト定義
A35: 事前条件 | G35: メッセージID（引数）
A36: 必須パラメーターがあるか。 | G36: E0202 | H36: （@ユーザー情報）
G37: E0202 | H37: （@システム日付）
G38: E0202 | H38: （@会社コード）
G39: E0202 | H39: （@エントリーコード）
G40: E0202 | H40: （@エントリー年）
G41: E0202 | H41: （@エントリー回）
A43: 事後条件 | G43: メッセージID（引数）
A48: ロジック定義
A49: 処理内容
A51: １．事前条件判断処理実行を行う。
A53: ２．リターン値Mapをインスタンス化する。
A55: ３．Dao【会社リスト】．検索 を実行し、実行結果[[会社リスト]]を取得する。
A56: パラメーター： | B56: パラメーター.ユーザー情報.ユーザーID
...

Sheet 【BEN016L02】検索対象情報取得
A2: [BIRD]ロジック設計書 | D2: =テンプレート!D2 -> 管理番号：DN-030103-019.01 分類 ：ロジック設計書 | G2: =テンプレート!G2 -> 更新者： 更新日： | I2: =テンプレート!I2 -> 作成者：ISID-IT 衣川 作成日：2006/12/27
A3: 検索対象情報取得
A4: 機能概要 | B4: 登録可能対象事業方針説明会情報を取得します。 | G4: TX属性 | H4: NotSupported
A5: ロジッククラス | B5: =CONCATENATE(テンプレート!B5, ".logic.impl.SearchLogicImpl") -> jp.co.isid.mos.bird.entry.nationalviewlist.logic.impl.SearchLogicImpl
A6: ロジックNO | B6: =CONCATENATE(テンプレート!B6,"02") -> BEN016L02 | C6: ステータス | D6: 暫定版 | J6: ステータスリスト
J7: 暫定版
A8: インタフェース定義 | J8: レビュー待ち
A9: パラメータ | J9: 確定版
A10: 項目名 | B10: データタイプ | C10: 内容 | G10: 必須 | H10: 初期値
A11: BIRDユーザー情報 | B11: BirdUserInfo | G11: ○
A12: 対象エントリー情報 | B12: entity | G12: ○
A13: システム日付 | B13: 文字列 | G13: ○
A14: 会社コード | B14: 文字列 | G14: ○
A15: 対象条件 | B15: 文字列 | G15: ○
A16: 支部コード | B16: 文字列 | G16: △
A17: SVコード | B17: 文字列 | G17: △
A21: リターン
A22: 項目名 | B22: データタイプ | C22: 内容 | G22: 初期値
A23: 出欠件数情報 | B23: List | C23: =CONCATENATE(テンプレート!B5, ".entity.UIAttendAbsentCntInfo") -> jp.co.isid.mos.bird.entry.nationalviewlist.entity.UIAttendAbsentCntInfo
A24: 申込状況一覧 | B24: List | C24: =CONCATENATE(テンプレート!B5, ".entity.UISibuOnerStatusList") -> jp.co.isid.mos.bird.entry.nationalviewlist.entity.UISibuOnerStatusList
A27: データI/O定義
A28: 使用Dao名 | C28: Daoクラス名
A29: 出欠件数情報 | B29: List | C29: =CONCATENATE(テンプレート!B5, ".dao.UIAttendAbsentCntInfoDao") -> jp.co.isid.mos.bird.entry.nationalviewlist.dao.UIAttendAbsentCntInfoDao
A30: 申込状況一覧 | B30: List | C30: =CONCATENATE(テンプレート!B5, ".dao.UISibuOnerStatusListDao") -> jp.co.isid.mos.bird.entry.nationalviewlist.dao.UISibuOnerStatusListDao
A35: コントラクト定義
A36: 事前条件 | G36: メッセージID（引数）
A37: 必須パラメーターがあるか。 | G37: E0202 | H37: （@ユーザー情報）
G38: E0202 | H38: （@対象エントリー情報）
G39: E0202 | H39: （@システム日付）
G40: E0202 | H40: （@会社コード）
G41: E0506 | H41: （@対象条件）
A42: 対象条件が支部の場合。 | G42: E0506 | H42: （@支部）
A43: 対象条件がSVコードの場合。 | G43: E0506 | H43: （@SVコード）
A45: 事後条件 | G45: メッセージID（引数）
A50: ロジック定義
A51: 処理内容
A53: １．事前条件処理を実行する。
A55: ２．リターン値Mapをインスタンス化する。
A57: ３．DAO【出欠件数情報】.検索を実行し、実行結果[[出欠件数情報]]をリターン値Mapへ格納する。
A58: パラメーター： | B58: パラメーター.エントリーコード
...

Sheet 【BEN016L03】CSV出力情報取得
A2: [BIRD]ロジック設計書 | D2: =テンプレート!D2 -> 管理番号：DN-030103-019.01 分類 ：ロジック設計書 | G2: 更新者：周春建 更新日：2014/05/30 | I2: =テンプレート!I2 -> 作成者：ISID-IT 衣川 作成日：2006/12/27
A3: CSV出力情報取得
A4: 機能概要 | B4: CSV出力情報を取得します。 | G4: TX属性 | H4: NotSupported
A5: ロジッククラス | B5: =CONCATENATE(テンプレート!B5, "logic.impl.CsvOutputLogicImpl") -> jp.co.isid.mos.bird.entry.nationalviewlistlogic.impl.CsvOutputLogicImpl
A6: ロジックNO | B6: =CONCATENATE(テンプレート!B6,"03") -> BEN016L03 | C6: ステータス | D6: 暫定版 | J6: ステータスリスト
J7: 暫定版
A8: インタフェース定義 | J8: レビュー待ち
A9: パラメータ | J9: 確定版
A10: 項目名 | B10: データタイプ | C10: 内容 | G10: 必須 | H10: 初期値
A11: DTO【申込状況確認】 | B11: DTO | C11: csvOutputDto | G11: ○
A20: ファイル名取得処理リターン
A21: 項目名 | B21: データタイプ | C21: 内容 | G21: 初期値
A22: CSVファイル名称 | B22: String
A24: CSV出力データ取得処理リターン
A25: 項目名 | B25: データタイプ | C25: 内容 | G25: 初期値
A26: CSV出力データ | B26: List | C26: =CONCATENATE(テンプレート!B5, ".entity.UICsvStatusList") -> jp.co.isid.mos.bird.entry.nationalviewlist.entity.UICsvStatusList
A30: データI/O定義
A31: 使用Dao名 | C31: Daoクラス名
A32: CSV申込状況一覧 | B32: List | C32: =CONCATENATE(テンプレート!B5, ".dao.UICsvStatusListDao") -> jp.co.isid.mos.bird.entry.nationalviewlist.dao.UICsvStatusListDao
A33: エントリーセレクション情報の取得処理 | B33: List | C33: jp.co.isid.mos.bird.entry.nationalviewlist.dao.UINatiEntrySelectInfoDao
A36: コントラクト定義
A37: 事前条件 | G37: メッセージID（引数）
A38: 入力値の必須は満たされているか？ | G38: E0202 | H38: （@DTO【申込状況確認】）
A42: 事後条件 | G42: メッセージID（引数）
A47: ロジック定義
A48: ファイル名取得処理内容
A50: １．パラメーター.DTO【申込状況確認】.区分＝’参加’の場合以下の名前をリターンする。
A51: ファイル名： ”NATIONAL_SANKA”
B52: ＋パラメーター.DTO【申込状況確認】.[対象エントリー情報].エントリー年
B53: ＋パラメーター.DTO【申込状況確認】.[対象エントリー情報].エントリー回
B54: ＋”.csv”
A56: ２．パラメーター.DTO【申込状況確認】.区分＝’不参加’の場合以下の名前をリターンする。
A57: ファイル名： ”NATIONAL_FUSANKA”
B58: ＋パラメーター.DTO【申込状況確認】.[対象エントリー情報].エントリー年
B59: ＋パラメーター.DTO【申込状況確認】.[対象エントリー情報].エントリー回
B60: ＋”.csv”
A62: ３．パラメーター.DTO【申込状況確認】.区分＝’未登録’の場合以下の名前をリターンする。
A63: ファイル名： ”NATIONAL_MITOUROKU”
B64: ＋パラメーター.DTO【申込状況確認】.[対象エントリー情報].エントリー年
B65: ＋パラメーター.DTO【申込状況確認】.[対象エントリー情報].エントリー回
...

Sheet 【BEN016L04】SVコード存在チェック
A2: [BIRD]ロジック設計書 | D2: =テンプレート!D2 -> 管理番号：DN-030103-019.01 分類 ：ロジック設計書 | G2: =テンプレート!G2 -> 更新者： 更新日： | I2: =テンプレート!I2 -> 作成者：ISID-IT 衣川 作成日：2006/12/27
A3: SVコード存在チェック
A4: 機能概要 | B4: SVコードの存在チェックを行います。 | G4: TX属性 | H4: NotSupported
A5: ロジッククラス | B5: =CONCATENATE(テンプレート!B5, "logic.impl.CheckSvExistLogicImpl") -> jp.co.isid.mos.bird.entry.nationalviewlistlogic.impl.CheckSvExistLogicImpl
A6: ロジックNO | B6: =CONCATENATE(テンプレート!B6,"04") -> BEN016L04 | C6: ステータス | D6: 暫定版 | J6: ステータスリスト
J7: 暫定版
A8: インタフェース定義 | J8: レビュー待ち
A9: パラメータ | J9: 確定版
A10: 項目名 | B10: データタイプ | C10: 内容 | G10: 必須 | H10: 初期値
A11: 会社コード | B11: 文字列 | G11: ○
A12: SVコード | B12: 文字列 | G12: ○
A15: リターン
A16: 項目名 | B16: データタイプ | C16: 内容 | G16: 初期値
A17: SVリスト | B17: List | C17: =CONCATENATE(テンプレート!B5, ".entity.CodSv") -> jp.co.isid.mos.bird.entry.nationalviewlist.entity.CodSv
A19: データI/O定義
A20: 使用Dao名 | C20: Daoクラス名
A21: SVリスト | B21: List | C21: =CONCATENATE(テンプレート!B5, ".dao.CodSvDao") -> jp.co.isid.mos.bird.entry.nationalviewlist.dao.CodSvDao
A27: コントラクト定義
A28: 事前条件 | G28: メッセージID（引数）
A29: 入力値の必須は満たされているか？ | G29: E0202 | H29: （@会社コード）
G30: E0506 | H30: （@SVコード）
A36: 事後条件 | G36: メッセージID（引数）
A41: ロジック定義
A42: 処理内容
A44: １．事前条件判断処理
A46: ２．パラメータ.SVコードを前ゼロ付加する。
A47: MSG【E0102】’該当データーがありません。’
A48: ３．Dao【SVリスト】の検索を実行する。
A50: ４．該当データが存在しない場合、下記のExceptionを発生させる。
B51: MSG【E0103】’が存在しません。’
B52: throw new NotExistException("該当SVコード", "targetSvCd",0);
A54: ５．パラメータ.SVコードをリターンする。
