Workbook
Name EntityClassPath: #REF!
Name MethodClassPath: #REF!

Sheet 変更履歴
B2: 承認履歴
B4: バージョン | C4: 変更管理NO | D4: 作成 | F4: レビュー | H4: 承認
D5: 担当者 | E5: 日付 | F5: 担当者 | G5: 日付 | H5: 担当者 | I5: 日付
B6: 01 | C6: 201405-001 | D6: 周春建 | E6: 41766 | F6: 王海軍 | G6: 41768
B7: 03 | D7: 田村雄一 | E7: 42864 | F7: 矢嶋一彦 | G7: 42864 | H7: 田中宣行 | I7: 42864
B15: 変更履歴
B17: バージョン | C17: 変更内容
B18: 01 | C18: CSV申込状況一覧(UICsvStatusList)シート： ・「生年月日」、「備考１」を追加する。 ・「備考」を「備考２」を修正する。 セレクション情報(UINatiEntrySelectInfo)シートを追加する。
B19: 03 | C19: 全国大会開催に伴う改修
C20: オプショナル（宿泊関連）の項目数を4個から10個変更、オプショナル（その他）を追加するための対応
C21: 「CSV申込状況一覧(UICsvStatusList)」
C22: オプショナル11～オプショナル30を追加

Sheet 設定＆実行
A2: [BIRD]Dao設計書 | C2: 管理番号：DN-030103-019.01 分類 ：開発標準化 | F2: 更新者： 更新日： | H2: 作成者：ASPAC 衣川 作成日：2006/12/19
A3: エンティティ出力先 | B3: C:\Temp
A6: 作成対象シート
A7: 申込状況一覧(UISibuOnerStatusList)
C22: FALSE

Sheet 記述例
A2: [BIRD]Dao設計書 | C2: 管理番号：DN-010104-003.01 分類 ：開発標準化 | E2: 更新者：ISID-IT 松本 更新日：2006/01/16 | F2: 作成者：ISID-IT 松本 作成日：2006/01/16
A3: クレーム情報(UIClaimInfo)
A5: WT18CLAM
A7: クレーム情報を取得する
A9: jp.co.isid.mos.bird.communication.cliaminfo.logic.entity.UIClaimInfo
A11: プロパティ名 | B11: 論理名 | C11: Java型 | D11: 列型 | E11: 参照 | F11: 説明
A12: claimNo | B12: 管理番号 | C12: String | D12: CHAR(11) | E12: CLAIM_NO | F12: 管理番号
A13: jusinDt | B13: 受信日 | C13: String | D13: CHAR(8) | E13: JUSIN_DT | F13: 受信した日
A14: miseCd | B14: 店コード | C14: String | D14: CHAR(5) | E14: MISE_CD | F14: 店コード
A15: miseNameKj | B15: 店名称 | C15: String | D15: CHAR(40) | E15: MISE_NAME_KJ | F15: 店名称
A16: sibuCd | B16: 支部コード | C16: String | D16: CHAR(3) | E16: SIBU_CD | F16: 支部コード
A17: sibuName | B17: 支部名称 | C17: String | D17: CHAR(20) | E17: SIBU_NAME | F17: 支部名称
A18: bnrMname | B18: 中分類名称 | C18: String | D18: CHAR(52) | E18: BNR_M_NAME | F18: 分類名１
A19: bnrSname | B19: 小分類名称 | C19: String | D19: CHAR(52) | E19: BNR_S_NAME | F19: 分類名２
A20: naiyou | B20: 内容 | C20: String | D20: VCHAR(1024) | E20: NAIYOU | F20: お客様の声（要約）
A21: tenpoTaiou | B21: 店舗対応 | C21: String | D21: CHAR(1024) | E21: TENPO_TAIOU | F21: 報告内容

Sheet 対象エントリー情報(UIEntryStatusInfo)
A2: [BIRD]Dao設計書 | C2: ='設定＆実行'!C2:D2 -> 管理番号：DN-030103-019.01 分類 ：開発標準化 | E2: ='設定＆実行'!F2 -> 更新者： 更新日： | G2: ='設定＆実行'!H2 -> 作成者：ASPAC 衣川 作成日：2006/12/19
A3: 対象エントリー情報(UIEntryStatusInfo)
A5: BR17ENTL
A7: 指定全国大会の情報を取得する。
A9: jp.co.isid.mos.bird.entry.nationalviewlist.entity.UIEntryStatusInfo
A11: プロパティ名 | B11: 論理名 | C11: Java型 | D11: 列型 | E11: 参照 | F11: 対象テーブル | G11: 説明
A12: =IF(ISERROR(FIND("_",E12)),LOWER(E12),CONCATENATE(LOWER(LEFT(E12,(FIND("_",E12))-1)),SUBSTITUTE(PROPER(LOWER(RIGHT(E12,LEN(E12)-FIND("_",E12)))),"_",""))) -> entryCd | B12: エントリーコード | C12: String | D12: CHAR(2) | E12: ENTRY_CD | F12: BR17ENTL
A13: =IF(ISERROR(FIND("_",E13)),LOWER(E13),CONCATENATE(LOWER(LEFT(E13,(FIND("_",E13))-1)),SUBSTITUTE(PROPER(LOWER(RIGHT(E13,LEN(E13)-FIND("_",E13)))),"_",""))) -> entryYear | B13: エントリー年 | C13: String | D13: CHAR(4) | E13: ENTRY_YEAR | F13: BR17ENTL
A14: =IF(ISERROR(FIND("_",E14)),LOWER(E14),CONCATENATE(LOWER(LEFT(E14,(FIND("_",E14))-1)),SUBSTITUTE(PROPER(LOWER(RIGHT(E14,LEN(E14)-FIND("_",E14)))),"_",""))) -> entryKai | B14: エントリー回 | C14: String | D14: CHAR(3) | E14: ENTRY_KAI | F14: BR17ENTL
A15: =IF(ISERROR(FIND("_",E15)),LOWER(E15),CONCATENATE(LOWER(LEFT(E15,(FIND("_",E15))-1)),SUBSTITUTE(PROPER(LOWER(RIGHT(E15,LEN(E15)-FIND("_",E15)))),"_",""))) -> kaisaiFromDt | B15: 開催日From | C15: String | D15: CHAR(8) | E15: KAISAI_FROM_DT | F15: BR18ENTD
A16: =IF(ISERROR(FIND("_",E16)),LOWER(E16),CONCATENATE(LOWER(LEFT(E16,(FIND("_",E16))-1)),SUBSTITUTE(PROPER(LOWER(RIGHT(E16,LEN(E16)-FIND("_",E16)))),"_",""))) -> kaisaiToDt | B16: 開催日To | C16: String | D16: CHAR(8) | E16: KAISAI_TO_DT | F16: BR18ENTD
A17: =IF(ISERROR(FIND("_",E17)),LOWER(E17),CONCATENATE(LOWER(LEFT(E17,(FIND("_",E17))-1)),SUBSTITUTE(PROPER(LOWER(RIGHT(E17,LEN(E17)-FIND("_",E17)))),"_",""))) -> entryTitle | B17: エントリータイトル（説明会名称） | C17: String | D17: CHAR(100) | E17: ENTRY_TITLE | F17: BR18ENTD | G17: 登録画面では最大全角30文字以内
A18: =IF(ISERROR(FIND("_",E18)),LOWER(E18),CONCATENATE(LOWER(LEFT(E18,(FIND("_",E18))-1)),SUBSTITUTE(PROPER(LOWER(RIGHT(E18,LEN(E18)-FIND("_",E18)))),"_",""))) -> honbuFromDt | B18: 開始日（本部申込開始日） | C18: String | D18: CHAR(8) | E18: HONBU_FROM_DT | F18: BR18ENTD
A19: =IF(ISERROR(FIND("_",E19)),LOWER(E19),CONCATENATE(LOWER(LEFT(E19,(FIND("_",E19))-1)),SUBSTITUTE(PROPER(LOWER(RIGHT(E19,LEN(E19)-FIND("_",E19)))),"_",""))) -> honbuToDt | B19: 終了日(本部申込終了日) | C19: String | D19: CHAR(8) | E19: HONBU_TO_DT | F19: BR18ENTD
A20: =IF(ISERROR(FIND("_",E20)),LOWER(E20),CONCATENATE(LOWER(LEFT(E20,(FIND("_",E20))-1)),SUBSTITUTE(PROPER(LOWER(RIGHT(E20,LEN(E20)-FIND("_",E20)))),"_",""))) -> onerFromDt | B20: 開始日（オーナー申込開始日） | C20: String | D20: CHAR(8) | E20: ONER_FROM_DT | F20: BR18ENTD
A21: =IF(ISERROR(FIND("_",E21)),LOWER(E21),CONCATENATE(LOWER(LEFT(E21,(FIND("_",E21))-1)),SUBSTITUTE(PROPER(LOWER(RIGHT(E21,LEN(E21)-FIND("_",E21)))),"_",""))) -> onerToDt | B21: 終了日(オーナー申込終了日) | C21: String | D21: CHAR(8) | E21: ONER_TO_DT | F21: BR18ENTD
A22: =IF(ISERROR(FIND("_",E22)),LOWER(E22),CONCATENATE(LOWER(LEFT(E22,(FIND("_",E22))-1)),SUBSTITUTE(PROPER(LOWER(RIGHT(E22,LEN(E22)-FIND("_",E22)))),"_",""))) -> onerAttendCnt | B22: オーナー参加or出席件数 | C22: String | D22: CHAR(1) | E22: ONER_ATTEND_CNT | F22: BT46KENS
A23: =IF(ISERROR(FIND("_",E23)),LOWER(E23),CONCATENATE(LOWER(LEFT(E23,(FIND("_",E23))-1)),SUBSTITUTE(PROPER(LOWER(RIGHT(E23,LEN(E23)-FIND("_",E23)))),"_",""))) -> onerAbsentCnt | B23: オーナー不参加or欠席件数 | C23: String | D23: CHAR(1) | E23: ONER_ABSENT_CNT | F23: BT46KENS
A25: Dao情報
A26: 対象エントリー情報(UIEntryStatusInfoDao)
A27: jp.co.isid.mos.bird.entry.nationalviewlist.dao.UIEntryStatusInfoDao
A29: 対象全国大会情報 (select)
A31: パラメータ情報 | E31: SQL
A32: エントリーコード | E32: SELECT BR17.ENTRY_CD
A33: エントリー年 | E33: , BR17.ENTRY_YEAR
A34: エントリー回 | E34: , BR17.ENTRY_KAI
A35: システム日付 | E35: , ENTRY.FROM_DT AS KAISAI_DT
E36: , BR17.ENTRY_TITLE AS ENTRY_TITLE
A37: 使用テーブル | E37: , HONBU.FROM_DT AS HONBU_FROM_DT
A38: グループ統合オーナーマスタ | B38: BM11ONER | E38: , HONBU.TO_DT AS HONBU_TO_DT
A39: 店統合マスタ | B39: BM01TENM | E39: , ONER.FROM_DT AS ONER_FROM_DT
E40: , ONER.TO_DT AS ONER_TO_DT
A41: エントリーマスタ管理 | B41: BR17ENTL | E41: , DECIMAL(CASE WHEN BT21.ATTEND_CNT IS NULL THEN 0 ELSE BT21.ATTEND_CNT END, 6,0) AS ONER_ATTEND_CNT
A42: エントリー日付管理 | B42: BR18ENTD | E42: , DECIMAL(CASE WHEN BT21.ABSENT_CNT IS NULL THEN 0 ELSE BT21.ABSENT_CNT END, 6,0) AS ONER_ABSENT_CNT
A43: オーナー別エントリー状況 | B43: BT20ENON
E44: FROM BR17ENTL BR17
A45: JOIN情報 | B45: BM11ONER : BM01TENM
A46: 結合条件 | B46: INNER | E46: JOIN (SELECT * FROM BR18ENTD WHERE USERTYPE_CD = '99' AND DAY_KBN = '01') ENTRY
A47: 当方連結キー | B47: グループ統合オーナーマスタ.会社コード | E47: ON (ENTRY.ENTRY_CD = BR17.ENTRY_CD AND ENTRY.ENTRY_YEAR = BR17.ENTRY_YEAR AND ENTRY.ENTRY_KAI = BR17.ENTRY_KAI)
A48: 先方連結キー | B48: 店統合マスタ.会社コード
...

Sheet 会社リスト(CodCompany)
A2: [BIRD]Dao設計書 | C2: ='設定＆実行'!C2:D2 -> 管理番号：DN-030103-019.01 分類 ：開発標準化 | E2: ='設定＆実行'!F2 -> 更新者： 更新日： | G2: ='設定＆実行'!H2 -> 作成者：ASPAC 衣川 作成日：2006/12/19
A3: 会社リスト(CodCompany)
A5: BM10GSIB
A7: 支部コード情報を取得
A9: jp.co.isid.mos.bird.entry.nationalviewlist.entity.CodCompany
A11: プロパティ名 | B11: 論理名 | C11: Java型 | D11: 列型 | E11: 参照 | F11: 対象テーブル | G11: 説明
A12: =IF(ISERROR(FIND("_",E12)),LOWER(E12),CONCATENATE(LOWER(LEFT(E12,(FIND("_",E12))-1)),SUBSTITUTE(PROPER(LOWER(RIGHT(E12,LEN(E12)-FIND("_",E12)))),"_",""))) -> companyCd | B12: 企業コード | C12: String | D12: CHAR(02) | E12: COMPANY_CD | F12: BC05KCOM | G12: 企業コード
A13: =IF(ISERROR(FIND("_",E13)),LOWER(E13),CONCATENATE(LOWER(LEFT(E13,(FIND("_",E13))-1)),SUBSTITUTE(PROPER(LOWER(RIGHT(E13,LEN(E13)-FIND("_",E13)))),"_",""))) -> companyName | B13: 会社名 | C13: String | D13: CHAR(40) | E13: COMPANY_NAME | F13: BC05KCOM | G13: 会社名
A16: Dao情報
A17: 会社コード(CodCompanyDao)
A18: jp.co.isid.mos.bird.entry.nationalviewlist.dao.CodCompanyDao
A20: 会社を取得する(select)
A22: パラメータ情報
A23: ユーザID
A26: 使用テーブル
A27: 管理会社 | B27: BC05KCOM
A28: ユーザ対応オーナー | B28: BM06UONR
A30: JOIN情報 | E30: SQL
A31: 結合条件 | E31: select bc02.r_company_cd as company_cd , bc02.company_name from bm03uscp as bm03 , bc02comp as bc02 where bm03.r_company_cd = bc02.r_company_cd and bm03.user_id = /*userId*/'99990003' and bc02.mise_flg = '1' order by bc02.sort_seq
A32: 当方連結キー
A33: 先方連結キー
A35: 条件
A40: ソート情報
A41: 管理会社.COMPANY_CD | B41: 昇順

Sheet 支部リスト(CodSibu)
A2: [BIRD]Dao設計書 | C2: ='設定＆実行'!C2:D2 -> 管理番号：DN-030103-019.01 分類 ：開発標準化 | E2: ='設定＆実行'!F2 -> 更新者： 更新日： | G2: ='設定＆実行'!H2 -> 作成者：ASPAC 衣川 作成日：2006/12/19
A3: 支部リスト(CodSibu)
A5: BM10GSIB
A7: 支部コード情報を取得
A9: jp.co.isid.mos.bird.entry.nationalviewlist.entity.CodSibu
A11: プロパティ名 | B11: 論理名 | C11: Java型 | D11: 列型 | E11: 参照 | F11: 対象テーブル | G11: 説明
A12: =IF(ISERROR(FIND("_",E12)),LOWER(E12),CONCATENATE(LOWER(LEFT(E12,(FIND("_",E12))-1)),SUBSTITUTE(PROPER(LOWER(RIGHT(E12,LEN(E12)-FIND("_",E12)))),"_",""))) -> companyCd | B12: 会社コード | C12: String | D12: CHAR(2) | E12: COMPANY_CD | F12: BM10GSIB
A13: =IF(ISERROR(FIND("_",E13)),LOWER(E13),CONCATENATE(LOWER(LEFT(E13,(FIND("_",E13))-1)),SUBSTITUTE(PROPER(LOWER(RIGHT(E13,LEN(E13)-FIND("_",E13)))),"_",""))) -> sibuCd | B13: 支部コード | C13: String | D13: CHAR(5) | E13: SIBU_CD | F13: BM10GSIB
A14: =IF(ISERROR(FIND("_",E14)),LOWER(E14),CONCATENATE(LOWER(LEFT(E14,(FIND("_",E14))-1)),SUBSTITUTE(PROPER(LOWER(RIGHT(E14,LEN(E14)-FIND("_",E14)))),"_",""))) -> sibuName | B14: 支部名称 | C14: String | D14: CHAR(40) | E14: SIBU_NAME | F14: BM10GSIB
A17: Dao情報
A18: 支部リスト(CodSibuDao)
A19: jp.co.isid.mos.bird.entry.nationalviewlist.dao.CodSibuDao
A21: 支部情報(select)
A23: パラメータ情報 | F23: SQL
A24: ユーザ制限フラグ | F24: select
A25: ユーザID | F25: rtrim(BM10.COMPANY_CD) as COMPANY_CD,
F26: rtrim(BM10.SIBU_CD) as SIBU_CD,
F27: rtrim(BM10.SIBU_NAME) as SIBU_NAME
A28: 使用テーブル | F28: from
A29: 汎用店舗グループ（支部） | B29: BM10GSIB | F29: BM10GSIB as BM10
A30: グループ結合オーナマスタ | B30: BM11ONER | F30: /*IF limit*/
A31: SV担当支部 | B31: BM51SVSB | F31: inner join BM51SVSB as BM51
F32: on BM51.COMPANY_CD = BM10.COMPANY_CD and BM51.SIBU_CD = BM10.SIBU_CD
A33: JOIN情報 | B33: BM51SVSB : BM10GSIB | F33: /*END*/
A34: 結合条件 | B34: JOIN | F34: where
A35: 当方連結キー | B35: SV担当支部.会社コード | F35: BM10.COMPANY_CD = /*companyCd*/'00' and
A36: 先方連結キー | B36: 汎用店舗グループ（支部）.会社コード | F36: BM10.HONBU_CD < '20000'
A37: 当方連結キー | B37: SV担当支部.支部コード | F37: /*IF limit*/
A38: 先方連結キー | B38: 汎用店舗グループ（支部）.支部コード | F38: and BM51.COMPANY_CD = /*companyCd*/'00'
F39: and BM51.SV_CD = /*userId*/'99990003'
A40: 条件 | F40: /*END*/
A41: 汎用店舗グループ（支部）.本部コード < 20000 | F41: order by
A42: SV担当支部.SVコード = （ユーザID） | F42: SIBU_CD
A45: ソート情報
A46: 支部コード | B46: 昇順

Sheet SVリスト(CodSv)
A2: [BIRD]Dao設計書 | C2: ='設定＆実行'!C2:D2 -> 管理番号：DN-030103-019.01 分類 ：開発標準化 | E2: ='設定＆実行'!F2 -> 更新者： 更新日： | G2: ='設定＆実行'!H2 -> 作成者：ASPAC 衣川 作成日：2006/12/19
A3: SVリスト(CodSv)
A5: BM52SVCD
A7: SVマスタからSVコード情報を取得
A9: jp.co.isid.mos.bird.entry.nationalviewlist.entity.CodSv
A11: プロパティ名 | B11: 論理名 | C11: Java型 | D11: 列型 | E11: 参照 | F11: 対象テーブル | G11: 説明
A12: =IF(ISERROR(FIND("_",E12)),LOWER(E12),CONCATENATE(LOWER(LEFT(E12,(FIND("_",E12))-1)),SUBSTITUTE(PROPER(LOWER(RIGHT(E12,LEN(E12)-FIND("_",E12)))),"_",""))) -> companyCd | B12: 会社コード | C12: String | D12: CHAR(2) | E12: COMPANY_CD | F12: BM52SVCD
A13: =IF(ISERROR(FIND("_",E13)),LOWER(E13),CONCATENATE(LOWER(LEFT(E13,(FIND("_",E13))-1)),SUBSTITUTE(PROPER(LOWER(RIGHT(E13,LEN(E13)-FIND("_",E13)))),"_",""))) -> svCd | B13: 支部コード | C13: String | D13: CHAR(5) | E13: SV_CD | F13: BM52SVCD
A14: =IF(ISERROR(FIND("_",E14)),LOWER(E14),CONCATENATE(LOWER(LEFT(E14,(FIND("_",E14))-1)),SUBSTITUTE(PROPER(LOWER(RIGHT(E14,LEN(E14)-FIND("_",E14)))),"_",""))) -> svNameKj | B14: 支部名称 | C14: String | D14: CHAR(40) | E14: SV_NAME_KJ | F14: BM52SVCD
A15: =IF(ISERROR(FIND("_",E15)),LOWER(E15),CONCATENATE(LOWER(LEFT(E15,(FIND("_",E15))-1)),SUBSTITUTE(PROPER(LOWER(RIGHT(E15,LEN(E15)-FIND("_",E15)))),"_",""))) -> svNameKna | B15: 支部名称 | C15: String | D15: CHAR(40) | E15: SV_NAME_KNA | F15: BM52SVCD
A18: Dao情報
A19: SVリスト(CodSvDao)
A20: jp.co.isid.mos.bird.entry.nationalviewlist.dao.CodSvDao
A22: 検索(select)
A24: パラメータ情報 | F24: SQL
A25: SVコード | F25: SELECT COMPANY_CD
F26: , SV_CD
F27: , rtrim(SV_NAME_KJ) AS SV_NAME_KJ
F28: , rtrim(SV_NAME_KANA) as SV_NAME_KNA
A29: 使用テーブル
A30: SVマスタ | B30: BM52SVCD | F30: FROM BM52SVCD
A32: 条件 | F32: WHERE SV_CD = /*svCd*/'00000085'
A33: SVマスタ.SVコード = パラメーターSVコード
A36: ソート情報
A37: 支部コード | B37: 昇順

Sheet 出欠件数情報(UIAttendAbsentCntInfo)
A2: [BIRD]Dao設計書 | C2: ='設定＆実行'!C2:D2 -> 管理番号：DN-030103-019.01 分類 ：開発標準化 | E2: ='設定＆実行'!F2 -> 更新者： 更新日： | G2: ='設定＆実行'!H2 -> 作成者：ASPAC 衣川 作成日：2006/12/19
A3: 出欠件数情報(UIAttendAbsentCntInfo)
A5: BT20ENON
A7: 対象全国大会のオーナー全体の出欠（参加・不参加）情報を取得する。
A9: jp.co.isid.mos.bird.entry.nationalviewlist.entity.UIAttendAbsentCntInfo
A11: プロパティ名 | B11: 論理名 | C11: Java型 | D11: 列型 | E11: 参照 | F11: 対象テーブル | G11: 説明
A12: =IF(ISERROR(FIND("_",E12)),LOWER(E12),CONCATENATE(LOWER(LEFT(E12,(FIND("_",E12))-1)),SUBSTITUTE(PROPER(LOWER(RIGHT(E12,LEN(E12)-FIND("_",E12)))),"_",""))) -> onerTotalCnt | B12: 全オーナー数 | C12: java.math.BigDecimal | D12: DEC（5） | E12: ONER_TOTAL_CNT | F12: Virtual
A13: =IF(ISERROR(FIND("_",E13)),LOWER(E13),CONCATENATE(LOWER(LEFT(E13,(FIND("_",E13))-1)),SUBSTITUTE(PROPER(LOWER(RIGHT(E13,LEN(E13)-FIND("_",E13)))),"_",""))) -> onerAttendCnt | B13: 参加オーナー | C13: java.math.BigDecimal | D13: DEC（5） | E13: ONER_ATTEND_CNT | F13: Virtual
A14: =IF(ISERROR(FIND("_",E14)),LOWER(E14),CONCATENATE(LOWER(LEFT(E14,(FIND("_",E14))-1)),SUBSTITUTE(PROPER(LOWER(RIGHT(E14,LEN(E14)-FIND("_",E14)))),"_",""))) -> onerAbsentCnt | B14: 不参加オーナー | C14: java.math.BigDecimal | D14: DEC（5） | E14: ONER_ABSENT_CNT | F14: Virtual
A15: =IF(ISERROR(FIND("_",E15)),LOWER(E15),CONCATENATE(LOWER(LEFT(E15,(FIND("_",E15))-1)),SUBSTITUTE(PROPER(LOWER(RIGHT(E15,LEN(E15)-FIND("_",E15)))),"_",""))) -> onerNoregistCnt | B15: 未登録オーナー | C15: java.math.BigDecimal | D15: DEC（5） | E15: ONER_NOREGIST_CNT | F15: Virtual
A16: =IF(ISERROR(FIND("_",E16)),LOWER(E16),CONCATENATE(LOWER(LEFT(E16,(FIND("_",E16))-1)),SUBSTITUTE(PROPER(LOWER(RIGHT(E16,LEN(E16)-FIND("_",E16)))),"_",""))) -> attendCnt | B16: 参加人数 | C16: java.math.BigDecimal | D16: DEC（6） | E16: ATTEND_CNT | F16: Virtual
A17: =IF(ISERROR(FIND("_",E17)),LOWER(E17),CONCATENATE(LOWER(LEFT(E17,(FIND("_",E17))-1)),SUBSTITUTE(PROPER(LOWER(RIGHT(E17,LEN(E17)-FIND("_",E17)))),"_",""))) -> absentCnt | B17: 不参加人数 | C17: java.math.BigDecimal | D17: DEC（6） | E17: ABSENT_CNT | F17: Virtual
A19: Dao情報
A20: 出欠件数情報(UIAttendAbsentCntInfoDao)
A21: jp.co.isid.mos.bird.entry.nationalviewlist.dao.UIAttendAbsentCntInfoDao
A23: オーナー全体出欠情報(select)
A25: パラメータ情報 | E25: SQL
A26: エントリーコード | E26: SELECT ONERTOTAL.CNT AS ONER_TOTAL_CNT
A27: エントリー年 | E27: , ONERCNT.ATTEND AS ONER_ATTEND_CNT
A28: エントリー回 | E28: , ONERCNT.ABSENT AS ONER_ABSENT_CNT
A29: システム日付 | E29: , PERSONCNT.ATTEND AS ATTEND_CNT
A30: 会社コード | E30: , PERSONCNT.ABSENT AS ABSENT_CNT
E32: FROM BR17ENTL BR17
A33: 使用テーブル | E33: , (SELECT COUNT(DISTINCT ONER.ONER_CD) AS CNT
A34: グループ統合オーナーマスタ | B34: BM11ONER | E34: FROM BM11ONER ONER
A35: 店統合マスタ | B35: BM01TENM | E35: , BM01TENM MISE
A36: エントリーマスタ管理 | B36: BR17ENTL | E36: WHERE ONER.COMPANY_CD = /*companyCd*/'00'
A37: エントリー日付管理 | B37: BR18ENTD | E37: AND ONER.ONER_CD != '39999'
A38: オーナー別エントリー状況 | B38: BT20ENON | E38: AND ONER.KEIYAKU_STA <= /*sysDate*/'20061213'
A39: 全国大会エントリー状況 | B39: BT48NATI | E39: AND ONER.KEIYAKU_END >= /*sysDate*/'20061213'
E40: AND MISE.COMPANY_CD = ONER.COMPANY_CD
A41: JOIN情報 | B41: BM11ONER : BM01TENM | E41: AND MISE.ONER_CD = ONER.ONER_CD
A42: 結合条件 | B42: INNER | E42: ) ONERTOTAL
A43: 当方連結キー | B43: グループ結合オーナマスタ.会社コード | E43: , (
A44: 先方連結キー | B44: 店統合マスタ.会社コード | E44: SELECT ENTRY_CD
A45: 当方連結キー | B45: グループ結合オーナマスタ.オーナーコード | E45: , ENTRY_YEAR
A46: 先方連結キー | B46: 店統合マスタ.オーナーコード | E46: , ENTRY_KAI
E47: , SUM(ATTEND) AS ATTEND
A48: JOIN情報 | B48: BM11ONER : BT20ENON | E48: , SUM(CASE WHEN ATTEND > 0 THEN 0 ELSE ABSENT END) AS ABSENT
A49: 結合条件 | B49: INNER | E49: FROM (SELECT BT20.ENTRY_CD
...

Sheet 申込状況一覧(UISibuOnerStatusList)
A2: [BIRD]Dao設計書 | C2: 管理番号：DN-030103-014.01 分類 ：Dao設計書 | E2: 更新者： 更新日： | F2: 作成者：ASPAC 丸山 作成日：2006/11/16
A3: 申込状況一覧(UISibuOnerStatusList)
A5: BT20ENON
A7: 事業方針説明会出欠一覧を取得する。
A9: jp.co.isid.mos.bird.entry.nationalviewlist.entity.UISibuOnerStatusList
A11: プロパティ名 | B11: 論理名 | C11: Java型 | D11: 列型 | E11: 参照 | F11: 対象テーブル | G11: 説明
A12: =IF(ISERROR(FIND("_",E12)),LOWER(E12),CONCATENATE(LOWER(LEFT(E12,(FIND("_",E12))-1)),SUBSTITUTE(PROPER(LOWER(RIGHT(E12,LEN(E12)-FIND("_",E12)))),"_",""))) -> sibuCd | B12: 支部コード | C12: String | D12: CHAR(3) | E12: SIBU_CD | F12: BM01TENM
A13: =IF(ISERROR(FIND("_",E13)),LOWER(E13),CONCATENATE(LOWER(LEFT(E13,(FIND("_",E13))-1)),SUBSTITUTE(PROPER(LOWER(RIGHT(E13,LEN(E13)-FIND("_",E13)))),"_",""))) -> sibuName | B13: 支部 | C13: String | D13: CHAR(40) | E13: SIBU_NAME | F13: BM11ONER
A14: =IF(ISERROR(FIND("_",E14)),LOWER(E14),CONCATENATE(LOWER(LEFT(E14,(FIND("_",E14))-1)),SUBSTITUTE(PROPER(LOWER(RIGHT(E14,LEN(E14)-FIND("_",E14)))),"_",""))) -> onerCd | B14: オーナーコード | C14: String | D14: CHAR(5) | E14: ONER_CD | F14: BM01TENM
A15: =IF(ISERROR(FIND("_",E15)),LOWER(E15),CONCATENATE(LOWER(LEFT(E15,(FIND("_",E15))-1)),SUBSTITUTE(PROPER(LOWER(RIGHT(E15,LEN(E15)-FIND("_",E15)))),"_",""))) -> onerNameKj | B15: オーナー名称 | C15: String | D15: CHAR(40) | E15: ONER_NAME_KJ | F15: BM10GSIB
A16: =IF(ISERROR(FIND("_",E16)),LOWER(E16),CONCATENATE(LOWER(LEFT(E16,(FIND("_",E16))-1)),SUBSTITUTE(PROPER(LOWER(RIGHT(E16,LEN(E16)-FIND("_",E16)))),"_",""))) -> entryFlg | B16: 参加フラグ | C16: BigDecimal | D16: DECIMAL(6) | E16: ENTRY_FLG | F16: BT20ENON | G16: 0：不参加 1：参加 空：未使用
A17: =IF(ISERROR(FIND("_",E17)),LOWER(E17),CONCATENATE(LOWER(LEFT(E17,(FIND("_",E17))-1)),SUBSTITUTE(PROPER(LOWER(RIGHT(E17,LEN(E17)-FIND("_",E17)))),"_",""))) -> attendCnt | B17: 参加人数 | C17: BigDecimal | D17: DECIMAL(6) | E17: ATTEND_CNT | F17: BT48NATI
A19: Dao情報
A20: 申込状況一覧(UISibuOnerStatusListDao)
A21: jp.co.isid.mos.bird.entry.nationalviewlist.dao.UISibuOnerStatusListDao
A23: 検索(select)
A25: パラメータ情報 | E25: SQL
A26: ユーザーID | E26: , (case when MAX(case when BT46.JIGYO_FLG = '0' then 1 else 0 end) > 0 then '○' else '×' end) as SHUSSEKI_KBN
A27: ユーザ制限フラグ
A28: エントリーコード
A29: エントリー年 | E29: FROM BT46KENS BT46
A30: エントリー回 | E30: , BM11ONER BM11
A31: システム日付 | E31: , BM01TENM BM01
A32: 会社コード
A33: 対象条件 | E33: WHERE BM11.COMPANY_CD = /*companyCd*/'00'
A34: 表示対象支部コード | E34: AND BM11.ONER_CD != '39999'
A35: 表示対象SVコード | E35: AND BM11.KEIYAKU_STA <= /*sysDate*/'20061213'
E36: AND BM11.KEIYAKU_END >= /*sysDate*/'20061213'
A37: 使用テーブル | E37: AND BT46.ENTRY_CD = /*entryCd*/'25'
A38: グループ統合オーナーマスタ | B38: BM11ONER | E38: AND BT46.ENTRY_YEAR = /*entryYear*/'2005'
A39: 店統合マスタ | B39: BM01TENM | E39: AND BT46.ENTRY_KAI = /*entryKai*/'001'
A40: エントリーマスタ管理 | B40: BR17ENTL | E40: AND BM01.COMPANY_CD = BM11.COMPANY_CD
A41: エントリー日付管理 | B41: BR18ENTD | E41: AND BT46.COMPANY_CD = BM01.COMPANY_CD
A42: オーナー別エントリー状況 | B42: BT20ENON | E42: AND BT46.ONER_CD = BM11.ONER_CD
A43: 全国大会エントリー状況 | B43: BT48NATI | E43: AND BT46.MISE_CD = BM01.MISE_CD
E44: GROUP BY BM11.ONER_CD
A45: JOIN情報 | B45: BM11ONER : BM01TENM | E45: ) SHUKKETU
A46: 結合条件 | B46: INNER | E46: ON (SHUKKETU.ONER_CD = BM11.ONER_CD)
A47: 当方連結キー | B47: グループ結合オーナマスタ.会社コード
A48: 先方連結キー | B48: 店統合マスタ.会社コード | E48: /*IF taishouJokenChoice.equals("2")*/
...

Sheet CSV申込状況一覧(UICsvStatusList)
A2: [BIRD]Dao設計書 | C2: ='設定＆実行'!C2:D2 -> 管理番号：DN-030103-019.01 分類 ：開発標準化 | E2: 更新者：ISID-AO 田村雄一 更新日：2017/05/09 | G2: ='設定＆実行'!H2 -> 作成者：ASPAC 衣川 作成日：2006/12/19
A3: CSV申込状況一覧(UICsvStatusList)
A5: BT48NATI
A7: CSV関連のデータを取得する。
A9: jp.co.isid.mos.bird.entry.nationalviewlist.entity.UICsvStatusList
A11: プロパティ名 | B11: 論理名 | C11: Java型 | D11: 列型 | E11: 参照 | F11: 対象テーブル | G11: 説明
A12: =IF(ISERROR(FIND("_",E12)),LOWER(E12),CONCATENATE(LOWER(LEFT(E12,(FIND("_",E12))-1)),SUBSTITUTE(PROPER(LOWER(RIGHT(E12,LEN(E12)-FIND("_",E12)))),"_",""))) -> sibuCd | B12: 支部コード | C12: String | D12: CHAR(5) | E12: SIBU_CD | F12: BM01TENM
A13: =IF(ISERROR(FIND("_",E13)),LOWER(E13),CONCATENATE(LOWER(LEFT(E13,(FIND("_",E13))-1)),SUBSTITUTE(PROPER(LOWER(RIGHT(E13,LEN(E13)-FIND("_",E13)))),"_",""))) -> sibuName | B13: 支部名称 | C13: String | D13: CHAR(40) | E13: SIBU_NAME | F13: BM10GSIB
A14: =IF(ISERROR(FIND("_",E14)),LOWER(E14),CONCATENATE(LOWER(LEFT(E14,(FIND("_",E14))-1)),SUBSTITUTE(PROPER(LOWER(RIGHT(E14,LEN(E14)-FIND("_",E14)))),"_",""))) -> onerCd | B14: オーナーコード | C14: String | D14: CHAR(5) | E14: ONER_CD | F14: BM01TENM
A15: =IF(ISERROR(FIND("_",E15)),LOWER(E15),CONCATENATE(LOWER(LEFT(E15,(FIND("_",E15))-1)),SUBSTITUTE(PROPER(LOWER(RIGHT(E15,LEN(E15)-FIND("_",E15)))),"_",""))) -> onerNameKj | B15: オーナー名称 | C15: String | D15: CHAR(40) | E15: ONER_NAME_KJ | F15: BM11ONER
A16: =IF(ISERROR(FIND("_",E16)),LOWER(E16),CONCATENATE(LOWER(LEFT(E16,(FIND("_",E16))-1)),SUBSTITUTE(PROPER(LOWER(RIGHT(E16,LEN(E16)-FIND("_",E16)))),"_",""))) -> seqNo | B16: ソート番号 | C16: String | D16: CHAR(1) | E16: SEQ_NO | F16: BT48NATI
A17: =IF(ISERROR(FIND("_",E17)),LOWER(E17),CONCATENATE(LOWER(LEFT(E17,(FIND("_",E17))-1)),SUBSTITUTE(PROPER(LOWER(RIGHT(E17,LEN(E17)-FIND("_",E17)))),"_",""))) -> miseCd | B17: 店舗コード | C17: String | D17: CHAR(5) | E17: MISE_CD | F17: BT48NATI
A18: =IF(ISERROR(FIND("_",E18)),LOWER(E18),CONCATENATE(LOWER(LEFT(E18,(FIND("_",E18))-1)),SUBSTITUTE(PROPER(LOWER(RIGHT(E18,LEN(E18)-FIND("_",E18)))),"_",""))) -> miseNameKj | B18: 店舗名称 | C18: String | D18: CHAR(40) | E18: MISE_NAME_KJ | F18: BM01TENM
A19: =IF(ISERROR(FIND("_",E19)),LOWER(E19),CONCATENATE(LOWER(LEFT(E19,(FIND("_",E19))-1)),SUBSTITUTE(PROPER(LOWER(RIGHT(E19,LEN(E19)-FIND("_",E19)))),"_",""))) -> lNameKj | B19: 参加者氏（漢字） | C19: String | D19: CHAR(20) | E19: L_NAME_KJ | F19: BT48NATI
A20: =IF(ISERROR(FIND("_",E20)),LOWER(E20),CONCATENATE(LOWER(LEFT(E20,(FIND("_",E20))-1)),SUBSTITUTE(PROPER(LOWER(RIGHT(E20,LEN(E20)-FIND("_",E20)))),"_",""))) -> fNameKj | B20: 参加者名（漢字） | C20: String | D20: CHAR(20) | E20: F_NAME_KJ | F20: BT48NATI
A21: =IF(ISERROR(FIND("_",E21)),LOWER(E21),CONCATENATE(LOWER(LEFT(E21,(FIND("_",E21))-1)),SUBSTITUTE(PROPER(LOWER(RIGHT(E21,LEN(E21)-FIND("_",E21)))),"_",""))) -> lNameKna | B21: 参加者氏（フリガナ） | C21: String | D21: CHAR(20) | E21: L_NAME_KNA | F21: BT48NATI
A22: =IF(ISERROR(FIND("_",E22)),LOWER(E22),CONCATENATE(LOWER(LEFT(E22,(FIND("_",E22))-1)),SUBSTITUTE(PROPER(LOWER(RIGHT(E22,LEN(E22)-FIND("_",E22)))),"_",""))) -> fNameKna | B22: 参加者名（フリガナ） | C22: String | D22: CHAR(20) | E22: F_NAME_KNA | F22: BT48NATI
A23: =IF(ISERROR(FIND("_",E23)),LOWER(E23),CONCATENATE(LOWER(LEFT(E23,(FIND("_",E23))-1)),SUBSTITUTE(PROPER(LOWER(RIGHT(E23,LEN(E23)-FIND("_",E23)))),"_",""))) -> sex | B23: 性別 | C23: String | D23: CHAR(1) | E23: SEX | F23: BT48NATI | G23: 男' or '女'
A24: =IF(ISERROR(FIND("_",E24)),LOWER(E24),CONCATENATE(LOWER(LEFT(E24,(FIND("_",E24))-1)),SUBSTITUTE(PROPER(LOWER(RIGHT(E24,LEN(E24)-FIND("_",E24)))),"_",""))) -> birthday | B24: 生年月日 | C24: String | D24: CHAR(8) | E24: BIRTHDAY | F24: BT48NATI | G24: 2014/05/07 生年月日を追加
A25: =IF(ISERROR(FIND("_",E25)),LOWER(E25),CONCATENATE(LOWER(LEFT(E25,(FIND("_",E25))-1)),SUBSTITUTE(PROPER(LOWER(RIGHT(E25,LEN(E25)-FIND("_",E25)))),"_",""))) -> age | B25: 年齢 | C25: String | D25: CHAR(3) | E25: AGE | F25: BT48NATI
A26: =IF(ISERROR(FIND("_",E26)),LOWER(E26),CONCATENATE(LOWER(LEFT(E26,(FIND("_",E26))-1)),SUBSTITUTE(PROPER(LOWER(RIGHT(E26,LEN(E26)-FIND("_",E26)))),"_",""))) -> jobType | B26: 職位 | C26: String | D26: CHAR(20) | E26: JOB_TYPE | F26: BT48NATI | G26: 全角のみ
A27: =IF(ISERROR(FIND("_",E27)),LOWER(E27),CONCATENATE(LOWER(LEFT(E27,(FIND("_",E27))-1)),SUBSTITUTE(PROPER(LOWER(RIGHT(E27,LEN(E27)-FIND("_",E27)))),"_",""))) -> proposeKbn | B27: 申込区分 | C27: String | D27: CHAR(2) | E27: PROPOSE_KBN | F27: BT48NATI | G27: 前ゼロ付加 99
A28: =IF(ISERROR(FIND("_",E28)),LOWER(E28),CONCATENATE(LOWER(LEFT(E28,(FIND("_",E28))-1)),SUBSTITUTE(PROPER(LOWER(RIGHT(E28,LEN(E28)-FIND("_",E28)))),"_",""))) -> optional1 | B28: オプショナル１の名称 | C28: String | D28: CHAR(30) | E28: OPTIONAL1 | F28: BT48NATI | G28: オプショナル（宿泊関連）1
A29: =IF(ISERROR(FIND("_",E29)),LOWER(E29),CONCATENATE(LOWER(LEFT(E29,(FIND("_",E29))-1)),SUBSTITUTE(PROPER(LOWER(RIGHT(E29,LEN(E29)-FIND("_",E29)))),"_",""))) -> optional2 | B29: オプショナル２の名称 | C29: String | D29: CHAR(30) | E29: OPTIONAL2 | F29: BT48NATI | G29: オプショナル（宿泊関連）2
A30: =IF(ISERROR(FIND("_",E30)),LOWER(E30),CONCATENATE(LOWER(LEFT(E30,(FIND("_",E30))-1)),SUBSTITUTE(PROPER(LOWER(RIGHT(E30,LEN(E30)-FIND("_",E30)))),"_",""))) -> optional3 | B30: オプショナル３の名称 | C30: String | D30: CHAR(30) | E30: OPTIONAL3 | F30: BT48NATI | G30: オプショナル（宿泊関連）3
A31: =IF(ISERROR(FIND("_",E31)),LOWER(E31),CONCATENATE(LOWER(LEFT(E31,(FIND("_",E31))-1)),SUBSTITUTE(PROPER(LOWER(RIGHT(E31,LEN(E31)-FIND("_",E31)))),"_",""))) -> optional4 | B31: オプショナル４の名称 | C31: String | D31: CHAR(30) | E31: OPTIONAL4 | F31: BT48NATI | G31: オプショナル（宿泊関連）4
A32: =IF(ISERROR(FIND("_",E32)),LOWER(E32),CONCATENATE(LOWER(LEFT(E32,(FIND("_",E32))-1)),SUBSTITUTE(PROPER(LOWER(RIGHT(E32,LEN(E32)-FIND("_",E32)))),"_",""))) -> optional5 | B32: オプショナル５の名称 | C32: String | D32: CHAR(30) | E32: OPTIONAL5 | F32: BT48NATI | G32: オプショナル（ツアー関連）1
A33: =IF(ISERROR(FIND("_",E33)),LOWER(E33),CONCATENATE(LOWER(LEFT(E33,(FIND("_",E33))-1)),SUBSTITUTE(PROPER(LOWER(RIGHT(E33,LEN(E33)-FIND("_",E33)))),"_",""))) -> optional6 | B33: オプショナル６の名称 | C33: String | D33: CHAR(30) | E33: OPTIONAL6 | F33: BT48NATI | G33: オプショナル（ツアー関連）2
A34: =IF(ISERROR(FIND("_",E34)),LOWER(E34),CONCATENATE(LOWER(LEFT(E34,(FIND("_",E34))-1)),SUBSTITUTE(PROPER(LOWER(RIGHT(E34,LEN(E34)-FIND("_",E34)))),"_",""))) -> optional7 | B34: オプショナル７の名称 | C34: String | D34: CHAR(30) | E34: OPTIONAL7 | F34: BT48NATI | G34: オプショナル（ツアー関連）3
A35: =IF(ISERROR(FIND("_",E35)),LOWER(E35),CONCATENATE(LOWER(LEFT(E35,(FIND("_",E35))-1)),SUBSTITUTE(PROPER(LOWER(RIGHT(E35,LEN(E35)-FIND("_",E35)))),"_",""))) -> optional8 | B35: オプショナル８の名称 | C35: String | D35: CHAR(30) | E35: OPTIONAL8 | F35: BT48NATI | G35: オプショナル（ツアー関連）4
A36: =IF(ISERROR(FIND("_",E36)),LOWER(E36),CONCATENATE(LOWER(LEFT(E36,(FIND("_",E36))-1)),SUBSTITUTE(PROPER(LOWER(RIGHT(E36,LEN(E36)-FIND("_",E36)))),"_",""))) -> optional9 | B36: オプショナル９の名称 | C36: String | D36: CHAR(30) | E36: OPTIONAL9 | F36: BT48NATI | G36: オプショナル（ツアー関連）5
A37: =IF(ISERROR(FIND("_",E37)),LOWER(E37),CONCATENATE(LOWER(LEFT(E37,(FIND("_",E37))-1)),SUBSTITUTE(PROPER(LOWER(RIGHT(E37,LEN(E37)-FIND("_",E37)))),"_",""))) -> optional10 | B37: オプショナル１０の名称 | C37: String | D37: CHAR(30) | E37: OPTIONAL10 | F37: BT48NATI | G37: オプショナル（ツアー関連）6
A38: =IF(ISERROR(FIND("_",E38)),LOWER(E38),CONCATENATE(LOWER(LEFT(E38,(FIND("_",E38))-1)),SUBSTITUTE(PROPER(LOWER(RIGHT(E38,LEN(E38)-FIND("_",E38)))),"_",""))) -> optional11 | B38: オプショナル１１の名称 | C38: String | D38: CHAR(30) | E38: OPTIONAL11 | F38: BT48NATI | G38: オプショナル（宿泊関連）5 | H38: Ver.03追加
A39: =IF(ISERROR(FIND("_",E39)),LOWER(E39),CONCATENATE(LOWER(LEFT(E39,(FIND("_",E39))-1)),SUBSTITUTE(PROPER(LOWER(RIGHT(E39,LEN(E39)-FIND("_",E39)))),"_",""))) -> optional12 | B39: オプショナル１２の名称 | C39: String | D39: CHAR(30) | E39: OPTIONAL12 | F39: BT48NATI | G39: オプショナル（宿泊関連）6 | H39: Ver.03追加
A40: =IF(ISERROR(FIND("_",E40)),LOWER(E40),CONCATENATE(LOWER(LEFT(E40,(FIND("_",E40))-1)),SUBSTITUTE(PROPER(LOWER(RIGHT(E40,LEN(E40)-FIND("_",E40)))),"_",""))) -> optional13 | B40: オプショナル１３の名称 | C40: String | D40: CHAR(30) | E40: OPTIONAL13 | F40: BT48NATI | G40: オプショナル（宿泊関連）7 | H40: Ver.03追加
A41: =IF(ISERROR(FIND("_",E41)),LOWER(E41),CONCATENATE(LOWER(LEFT(E41,(FIND("_",E41))-1)),SUBSTITUTE(PROPER(LOWER(RIGHT(E41,LEN(E41)-FIND("_",E41)))),"_",""))) -> optional14 | B41: オプショナル１４の名称 | C41: String | D41: CHAR(30) | E41: OPTIONAL14 | F41: BT48NATI | G41: オプショナル（宿泊関連）8 | H41: Ver.03追加
A42: =IF(ISERROR(FIND("_",E42)),LOWER(E42),CONCATENATE(LOWER(LEFT(E42,(FIND("_",E42))-1)),SUBSTITUTE(PROPER(LOWER(RIGHT(E42,LEN(E42)-FIND("_",E42)))),"_",""))) -> optional15 | B42: オプショナル１５の名称 | C42: String | D42: CHAR(30) | E42: OPTIONAL15 | F42: BT48NATI | G42: オプショナル（宿泊関連）9 | H42: Ver.03追加
A43: =IF(ISERROR(FIND("_",E43)),LOWER(E43),CONCATENATE(LOWER(LEFT(E43,(FIND("_",E43))-1)),SUBSTITUTE(PROPER(LOWER(RIGHT(E43,LEN(E43)-FIND("_",E43)))),"_",""))) -> optional16 | B43: オプショナル１６の名称 | C43: String | D43: CHAR(30) | E43: OPTIONAL16 | F43: BT48NATI | G43: オプショナル（宿泊関連）10 | H43: Ver.03追加
A44: =IF(ISERROR(FIND("_",E44)),LOWER(E44),CONCATENATE(LOWER(LEFT(E44,(FIND("_",E44))-1)),SUBSTITUTE(PROPER(LOWER(RIGHT(E44,LEN(E44)-FIND("_",E44)))),"_",""))) -> optional21 | B44: オプショナル２１の名称 | C44: String | D44: CHAR(30) | E44: OPTIONAL21 | F44: BT48NATI | G44: オプショナル（その他）1 | H44: Ver.03追加
A45: =IF(ISERROR(FIND("_",E45)),LOWER(E45),CONCATENATE(LOWER(LEFT(E45,(FIND("_",E45))-1)),SUBSTITUTE(PROPER(LOWER(RIGHT(E45,LEN(E45)-FIND("_",E45)))),"_",""))) -> optional22 | B45: オプショナル２２の名称 | C45: String | D45: CHAR(30) | E45: OPTIONAL22 | F45: BT48NATI | G45: オプショナル（その他）2 | H45: Ver.03追加
...

Sheet セレクション情報(UINatiEntrySelectInfo)
A2: [BIRD]Dao設計書 | C2: ='設定＆実行'!C2:D2 -> 管理番号：DN-030103-019.01 分類 ：開発標準化 | E2: 更新者： 更新日： | H2: 作成者：SHSC 周春建 作成日：2014/05/07
A3: セレクション情報(UINatiEntrySelectInfo)
A5: BR53ENTS
A7: エントリーセレクションの情報を取得する
A9: jp.co.isid.mos.bird.entry.nationalviewlist.entity.UINatiEntrySelectInfo
A11: プロパティ名 | B11: 論理名 | C11: Java型 | D11: 列型 | E11: 参照 | F11: 対象テーブル | G11: 説明
A12: =IF(ISERROR(FIND("_",E12)),LOWER(E12),CONCATENATE(LOWER(LEFT(E12,(FIND("_",E12))-1)),SUBSTITUTE(PROPER(LOWER(RIGHT(E12,LEN(E12)-FIND("_",E12)))),"_",""))) -> selectionKbn | B12: セレクション区分 | C12: String | D12: CHAR(5) | E12: SELECTION_KBN
A13: =IF(ISERROR(FIND("_",E13)),LOWER(E13),CONCATENATE(LOWER(LEFT(E13,(FIND("_",E13))-1)),SUBSTITUTE(PROPER(LOWER(RIGHT(E13,LEN(E13)-FIND("_",E13)))),"_",""))) -> selectionIndex | B13: セレクションインデックス | C13: String | D13: CHAR(47) | E13: SELECTION_INDEX
A14: =IF(ISERROR(FIND("_",E14)),LOWER(E14),CONCATENATE(LOWER(LEFT(E14,(FIND("_",E14))-1)),SUBSTITUTE(PROPER(LOWER(RIGHT(E14,LEN(E14)-FIND("_",E14)))),"_",""))) -> selectionName | B14: セレクション名称 | C14: String | D14: CHAR(5) | E14: SELECTION_NAME
A15: - | B15: セレクション名称有無 | C15: boolean | D15: - | E15: - | F15: - | G15: プロパティselectionNameの値から設定有無の判断処理を行うメソッド。メソッド名：isSelectionEmpty()
A18: Dao情報
A19: セレクション情報取得DAO（UINatiEntrySelectInfoDao）
A20: jp.co.isid.mos.bird.entry.nationalviewlist.dao.UINatiEntrySelectInfoDao
A22: エントリーセレクション情報の取得 (getNatiEntrySelectInfo)
A24: パラメータ情報
A25: エントリーコード
A26: エントリー年
A27: エントリー回
A28: セレクション区分
A30: 使用テーブル
A31: エントリーセレクション管理 | B31: BR53ENTS
A35: 条件
A36: エントリーセレクション管理.エントリコード = 'エントリーコード' | C36: AND
A37: エントリーセレクション管理.エントリー年 = 'エントリー年' | C37: AND
A38: エントリーセレクション管理.エントリー回 = 'エントリー回' | C38: AND
A39: エントリーセレクション管理.セレクション区分 = 'セレクション区分' | I39: 2012/06/21 xkinu 削除 改修(申込・オプショナル（宿泊・ツアー関連）歯抜け）対応
